Workbook

Sheet Summary
A1: Niumee AI Receptionist V2 - Accuracy Evaluation
A2: 151 questions from Clarissa's 'AI WHATSAPP Q&A ON SERVICES_v2.xlsx' replayed against the no-send test bot (n8n test mirror), one WhatsApp session per category, 21 Jul 2026. Graded vs Clarissa's approved answers: PASS=1, PARTIAL=0.5, FAIL=0.
A5: Category | B5: Questions | C5: Pass | D5: Partial | E5: Fail | F5: First-run accuracy | G5: FINAL accuracy | H5: V1 baseline*
A6: LASER HAIR REMOVAL | B6: =COUNTA('LASER HAIR REMOVAL'!B2:B200) -> 19 | C6: =COUNTIF('LASER HAIR REMOVAL'!G2:G200,"PASS") -> 15 | D6: =COUNTIF('LASER HAIR REMOVAL'!G2:G200,"PARTIAL") -> 4 | E6: =COUNTIF('LASER HAIR REMOVAL'!G2:G200,"FAIL") -> 0 | F6: =(COUNTIF('LASER HAIR REMOVAL'!E2:E200,"PASS")+0.5*COUNTIF('LASER HAIR REMOVAL'!E2:E200,"PARTIAL"))/B6 -> 0.78947368 | G6: =(C6+0.5*D6)/B6 -> 0.89473684 | H6: =1-COUNTIF('LASER HAIR REMOVAL'!C2:C200,"Bad")/B6 -> 0.94736842
A7: SEMI-PERMANENT MAKEUP | B7: =COUNTA('SEMI-PERMANENT MAKEUP'!B2:B200) -> 18 | C7: =COUNTIF('SEMI-PERMANENT MAKEUP'!G2:G200,"PASS") -> 17 | D7: =COUNTIF('SEMI-PERMANENT MAKEUP'!G2:G200,"PARTIAL") -> 1 | E7: =COUNTIF('SEMI-PERMANENT MAKEUP'!G2:G200,"FAIL") -> 0 | F7: =(COUNTIF('SEMI-PERMANENT MAKEUP'!E2:E200,"PASS")+0.5*COUNTIF('SEMI-PERMANENT MAKEUP'!E2:E200,"PARTIAL"))/B7 -> 0.80555556 | G7: =(C7+0.5*D7)/B7 -> 0.97222222 | H7: =1-COUNTIF('SEMI-PERMANENT MAKEUP'!C2:C200,"Bad")/B7 -> 1
A8: FACIALS | B8: =COUNTA(FACIALS!B2:B200) -> 18 | C8: =COUNTIF(FACIALS!G2:G200,"PASS") -> 4 | D8: =COUNTIF(FACIALS!G2:G200,"PARTIAL") -> 2 | E8: =COUNTIF(FACIALS!G2:G200,"FAIL") -> 12 | F8: =(COUNTIF(FACIALS!E2:E200,"PASS")+0.5*COUNTIF(FACIALS!E2:E200,"PARTIAL"))/B8 -> 0.22222222 | G8: =(C8+0.5*D8)/B8 -> 0.27777778 | H8: =1-COUNTIF(FACIALS!C2:C200,"Bad")/B8 -> 1
A9: NAILS | B9: =COUNTA(NAILS!B2:B200) -> 15 | C9: =COUNTIF(NAILS!G2:G200,"PASS") -> 10 | D9: =COUNTIF(NAILS!G2:G200,"PARTIAL") -> 4 | E9: =COUNTIF(NAILS!G2:G200,"FAIL") -> 1 | F9: =(COUNTIF(NAILS!E2:E200,"PASS")+0.5*COUNTIF(NAILS!E2:E200,"PARTIAL"))/B9 -> 0.53333333 | G9: =(C9+0.5*D9)/B9 -> 0.8 | H9: =1-COUNTIF(NAILS!C2:C200,"Bad")/B9 -> 1
A10: BOTOX & FILLERS | B10: =COUNTA('BOTOX & FILLERS'!B2:B200) -> 17 | C10: =COUNTIF('BOTOX & FILLERS'!G2:G200,"PASS") -> 16 | D10: =COUNTIF('BOTOX & FILLERS'!G2:G200,"PARTIAL") -> 1 | E10: =COUNTIF('BOTOX & FILLERS'!G2:G200,"FAIL") -> 0 | F10: =(COUNTIF('BOTOX & FILLERS'!E2:E200,"PASS")+0.5*COUNTIF('BOTOX & FILLERS'!E2:E200,"PARTIAL"))/B10 -> 0.85294118 | G10: =(C10+0.5*D10)/B10 -> 0.97058824 | H10: =1-COUNTIF('BOTOX & FILLERS'!C2:C200,"Bad")/B10 -> 0.58823529
A11: SKIN BOOSTERS | B11: =COUNTA('SKIN BOOSTERS'!B2:B200) -> 17 | C11: =COUNTIF('SKIN BOOSTERS'!G2:G200,"PASS") -> 14 | D11: =COUNTIF('SKIN BOOSTERS'!G2:G200,"PARTIAL") -> 3 | E11: =COUNTIF('SKIN BOOSTERS'!G2:G200,"FAIL") -> 0 | F11: =(COUNTIF('SKIN BOOSTERS'!E2:E200,"PASS")+0.5*COUNTIF('SKIN BOOSTERS'!E2:E200,"PARTIAL"))/B11 -> 0.088235294 | G11: =(C11+0.5*D11)/B11 -> 0.91176471 | H11: =1-COUNTIF('SKIN BOOSTERS'!C2:C200,"Bad")/B11 -> 0.70588235
A12: GYNAE | B12: =COUNTA(GYNAE!B2:B200) -> 11 | C12: =COUNTIF(GYNAE!G2:G200,"PASS") -> 4 | D12: =COUNTIF(GYNAE!G2:G200,"PARTIAL") -> 7 | E12: =COUNTIF(GYNAE!G2:G200,"FAIL") -> 0 | F12: =(COUNTIF(GYNAE!E2:E200,"PASS")+0.5*COUNTIF(GYNAE!E2:E200,"PARTIAL"))/B12 -> 0.54545455 | G12: =(C12+0.5*D12)/B12 -> 0.68181818 | H12: =1-COUNTIF(GYNAE!C2:C200,"Bad")/B12 -> 0.63636364
A13: Sports Therapy | B13: =COUNTA('Sports Therapy'!B2:B200) -> 17 | C13: =COUNTIF('Sports Therapy'!G2:G200,"PASS") -> 15 | D13: =COUNTIF('Sports Therapy'!G2:G200,"PARTIAL") -> 0 | E13: =COUNTIF('Sports Therapy'!G2:G200,"FAIL") -> 2 | F13: =(COUNTIF('Sports Therapy'!E2:E200,"PASS")+0.5*COUNTIF('Sports Therapy'!E2:E200,"PARTIAL"))/B13 -> 0.73529412 | G13: =(C13+0.5*D13)/B13 -> 0.88235294 | H13: =1-COUNTIF('Sports Therapy'!C2:C200,"Bad")/B13 -> 0.64705882
A14: PODOLOGY | B14: =COUNTA(PODOLOGY!B2:B200) -> 1 | C14: =COUNTIF(PODOLOGY!G2:G200,"PASS") -> 0 | D14: =COUNTIF(PODOLOGY!G2:G200,"PARTIAL") -> 0 | E14: =COUNTIF(PODOLOGY!G2:G200,"FAIL") -> 1 | F14: =(COUNTIF(PODOLOGY!E2:E200,"PASS")+0.5*COUNTIF(PODOLOGY!E2:E200,"PARTIAL"))/B14 -> 0 | G14: =(C14+0.5*D14)/B14 -> 0 | H14: =1-COUNTIF(PODOLOGY!C2:C200,"Bad")/B14 -> 0
A15: SCLEROTHERAPY | B15: =COUNTA(SCLEROTHERAPY!B2:B200) -> 18 | C15: =COUNTIF(SCLEROTHERAPY!G2:G200,"PASS") -> 13 | D15: =COUNTIF(SCLEROTHERAPY!G2:G200,"PARTIAL") -> 4 | E15: =COUNTIF(SCLEROTHERAPY!G2:G200,"FAIL") -> 1 | F15: =(COUNTIF(SCLEROTHERAPY!E2:E200,"PASS")+0.5*COUNTIF(SCLEROTHERAPY!E2:E200,"PARTIAL"))/B15 -> 0.69444444 | G15: =(C15+0.5*D15)/B15 -> 0.83333333 | H15: =1-COUNTIF(SCLEROTHERAPY!C2:C200,"Bad")/B15 -> 0.94444444
A16: OVERALL | B16: =SUM(B6:B15) -> 151 | C16: =SUM(C6:C15) -> 108 | D16: =SUM(D6:D15) -> 26 | E16: =SUM(E6:E15) -> 17 | F16: =SUMPRODUCT(F6:F15,B6:B15)/B16 -> 0.58609272 | G16: =(C16+0.5*D16)/B16 -> 0.8013245 | H16: =SUMPRODUCT(H6:H15,B6:B15)/B16 -> 0.83443709
A18: *V1 baseline = share of questions Clarissa did NOT flag as bad in her file (her grading was more lenient than this re-grade, so compare trends, not absolutes). 'FINAL grade' = after the V2.1 fixes deployed 21 Jul (context-aware policy detection, Skin Boosters knowledge row, website-tool truncation, privacy rule). Questions not re-tested keep their first-run grade.

Sheet LASER HAIR REMOVAL
A1: # | B1: Question | C1: V1 verdict (Clarissa) | D1: Bot answer - first run (21 Jul) | E1: First-run grade | F1: Bot answer - after V2.1 fixes | G1: FINAL grade | H1: Grader comment | I1: Clarissa approved answer
A2: 1 | B2: Do you offer this service? | C2: Good | D2: Yes, we do offer laser hair removal services! Here are the available options: 1) Add on BLT Anaesthetic for Laser hair removal (15 min) 2) Girls Open Day - Laser Hair Removal Consultation & Test patch with Nurse (15 min) 3) Laser hair removal Fingers & Toes by nurse (15 min) 4) Laser hair removal - full chest, abdomen + shoulders - by doctor (45 min) 5) Laser hair removal - upper lip by nurse (15 min) 6) Laser hair removal 15mins by Dr Pillow (0 min) 7) Laser hair removal bikini - by nurse (15 min) 8) Laser hair removal bikini + buttocks - by doctor (30 min) Please let me know which option you would like to know more about or if you'd like to proceed with any of them! 😊 | E2: PARTIAL | G2: PARTIAL | H2: Correct yes + options, but missing free consultation & patch test point | I2: Yes, we offer laser hair removal at Niumee. A free consultation and patch test are required before treatment to assess your skin and hair type and determine the most suitable settings.
A3: 2 | B3: What does the treatment do? | C3: Good | D3: Laser hair removal is an advanced, non-invasive treatment designed to safely and effectively reduce unwanted hair long-term. What it does: Targets hair follicles to achieve long-lasting hair reduction, leading to smoother skin. Helps minimize ingrown hairs and reduces the need for regular shaving or waxing. How it works: The XLase technology utilizes concentrated pulses of laser light absorbed by the pigment in hair follicles. This energy converts to heat, selectively damaging the follicle to inhibit future hair growth while maintaining the surrounding skin. Treatment protocol: Typically involves 3-6 sessions, spaced 4 weeks apart. Benefits: Long-term reduction of unwanted hair. Improved skin smoothness and reduced ingrown hairs. For more details, you can visit [this link](https://niumee.com/treatments/laser-hair-removal/). If you have more specific questions or if you'd like to book a session, let me know! 😊 | E3: PASS | G3: PASS | I3: Laser hair removal targets the hair follicles to reduce unwanted hair growth over time. With a course of treatments, the hair usually becomes finer, lighter, and grows back more slowly, helping to achieve smoother skin and longer-lasting results.
A4: 3 | B4: What are the benefits? | C4: Good | D4: The benefits of laser hair removal include: Long-term hair reduction: This treatment effectively targets hair follicles, providing lasting results and reducing the need for constant shaving or waxing. Smoother skin: By reducing unwanted hair, clients often achieve a smoother skin texture. Minimized ingrown hairs: The treatment helps reduce the occurrence of ingrown hairs, which can be an issue with traditional hair removal methods. Convenience: With fewer maintenance sessions required over time, it offers a more convenient solution to unwanted hair. If you need more information or would like to schedule a session, just let me know! 😊 | E4: PASS | G4: PASS | I4: Laser hair removal provides long-term hair reduction, helps hair grow back finer and more slowly, and can reduce ingrown hairs, razor irritation, and the need for frequent shaving or waxing. It also helps leave the skin feeling smoother over time.
A5: 4 | B5: Are there any side effects or contraindications? | C5: Good | D5: Side effects and contraindications of laser hair removal include: Possible Side Effects: Redness and swelling: Temporary irritation in the treated area is common following the treatment. Discoloration: Some clients may experience changes in skin pigmentation, especially those with darker skin tones. Sensitivity: Treated areas might feel more sensitive to temperature or touch for a short time. Contraindications: Not effective for certain hair types: The treatment is less effective on white, grey, or red hair due to lower melanin levels. Skin conditions: Active infections, eczema, or psoriasis in the treatment area may prevent treatment. Pregnancy: Women who are pregnant or breastfeeding should consult with a doctor before proceeding. Tanned skin: Avoid treatment if you have recently tanned your skin or used tanning products. For any specific concerns or if you'd like to schedule a consultation to discuss this in detail, feel free to ask! 😊 | E5: PASS | G5: PASS | I5: Well Informed.
A6: 5 | B6: Can I have sun exposure after the treatment? If yes, after how long? | C6: Good | D6: After laser hair removal treatment, it's generally recommended to avoid sun exposure for about 24-48 hours. This allows the skin to recover and reduces the risk of irritation and pigmentation changes. Once this initial period is over, if you need to be in the sun, make sure to apply a broad-spectrum sunscreen with SPF to protect the treated area. For any specific concerns or further questions, feel free to reach out! 😊 | E6: PASS | G6: PASS | I6: Well Informed.
A7: 6 | B7: Are there any precautions before or after the treatment? | C7: Good | D7: Before and after laser hair removal treatment, here are some precautions to keep in mind: Before Treatment: Avoid Sun Exposure: Refrain from sunbathing or using tanning beds for at least 4-6 weeks prior to your session to reduce the risk of skin damage. Shaving: You should shave the treatment area 24 hours before your appointment. Avoid waxing or plucking, as these can irritate the skin and disrupt the hair follicle. Skin Care Products: Avoid using products that irritate the skin (such as retinoids or acne treatments) in the days leading up to your treatment. After Treatment: Sun Protection: As discussed, avoid sun exposure for 24-48 hours post-treatment. Use sunscreen with a high SPF on any treated areas afterward. Avoid Hot Showers/ Saunas: Steer clear of hot showers, saunas, or intense workouts for at least 24 hours, as they can irritate the skin. Do Not Scratch or Rub: Avoid touching or scratching the treated area; let it heal naturally. If you have any specific questions or would like to book a session, just let me know! 😊 | E7: PASS | G7: PASS | I7: Well Informed.
A8: 7 | B8: How much does it cost? | C8: Good | D8: The cost for laser hair removal varies depending on the specific area you want to treat. Here are some options: Full Body Male: €200 Upper Lip: €30 Bikini Area: €30 Fingers & Toes: €30 These treatments typically require multiple sessions, usually spaced about 4 weeks apart. If you have any specific areas in mind or would like to schedule a session, just let me know! 😊 | E8: PARTIAL | G8: PARTIAL | H8: Per-area prices OK but didn't offer laser cards here | I8: You may pay per treatment area or choose one of our non-expiring laser cards: 1.5 hours – €150 3 hours – €285 6 hours – €459
A9: 8 | B9: Who performs this treatment? | C9: Good | D9: The laser hair removal treatments are performed by qualified nurses at Niumee: Chanelle, Jamie, and Ella. If you would like to book a session with one of them or have more questions, feel free to ask! 😊 | E9: FAIL | F9: Laser hair removal is performed by our trained and qualified laser practitioners: Jamie Liza Nevena Ella If you have any more questions or need further assistance, just let me know! 😊 | G9: PASS | H9: V2.1: correct list - Jamie, Liza, Nevena, Ella | I9: Laser hair removal is performed by our trained and qualified laser practitioners; Jamie, Liza, Nevena and Ella
A10: 9 | B10: How long does the treatment take? | C10: Good | D10: The duration for laser hair removal treatments typically lasts around 15 minutes for smaller areas, such as the upper lip or fingers, and can take up to 90 minutes for a full body session. Most treatments require multiple sessions spaced about 4 weeks apart to achieve optimal results. If you have any other questions or would like to book a session, just let me know! 😊 | E10: PASS | G10: PASS | I10: Treatment time depends on the area being treated. Smaller areas may take around 15 minutes, while larger or multiple areas may require longer. The expected duration will be confirmed during your consultation.
A11: 10 | B11: What is the treatment protocol? | C11: Good | D11: The treatment protocol for laser hair removal generally involves: Sessions: Usually between 3 to 6 sessions, depending on the area and individual concerns. Spacing: Treatments are typically spaced about 4 weeks apart to allow the hair to grow in cycles and ensure maximum effectiveness. Post-Treatment Care: It's important to avoid sun exposure and certain skincare products immediately after treatment, as well as refrain from waxing or plucking until the next session. If you have more questions or want to book a session, just let me know! 😊 | E11: PARTIAL | G11: PARTIAL | H11: Missing consultation+patch-test start; 4wk vs 4-8wk | I11: The process begins with a free consultation and patch test to assess your skin and hair type. Before each session, the treatment area should be shaved and free from creams, oils, deodorant, or fake tan. During treatment, the laser targets the hair follicles to reduce future growth. Sessions are usually repeated every 4–8 weeks, depending on the area and hair-growth cycle, and a course of treatments is normally required for the best results.
A12: 11 | B12: After how long is the treatment repeated? | C12: Good | D12: Laser hair removal treatments are typically repeated every 4 weeks. This spacing allows the hair to grow in cycles, ensuring optimal effectiveness for each session. If you have more questions or want to schedule a session, just let me know! 😊 | E12: PARTIAL | G12: PARTIAL | H12: Said every 4 weeks; approved is 4-8 weeks | I12: Laser hair removal sessions are usually repeated every 4–8 weeks, depending on the treatment area, hair-growth cycle, and your practitioner’s recommendation. Facial areas may require shorter intervals, while body areas are often treated less frequently.
A13: 12 | B13: How many sessions are required? | C13: Good | D13: Typically, most clients require between 3 to 6 sessions of laser hair removal, depending on the specific area and individual hair growth patterns. If you have more questions or would like to book a session, just let me know! 😊 | E13: PASS | G13: PASS | I13: Well Informed.
A14: 13 | B14: Is it painful? | C14: Good | D14: Many clients describe the sensation during laser hair removal as a mild discomfort, similar to a rubber band snapping against the skin. However, it generally isn't considered painful. Most treatments also use a cooling mechanism to help alleviate any discomfort during the procedure. If you have any more questions or wish to book a session, feel free to ask! 😊 | E14: PASS | G14: PASS | I14: Well Informed.
A15: 14 | B15: What is the minimum or maximum age allowed for this treatment? | C15: Good | D15: Laser hair removal is usually safe for clients aged 16 and above, but it is recommended that minors have parental or guardian consent. There isn't typically a strict upper age limit for this treatment as long as the individual is in good health. If you have more questions or would like to book a session, just let me know! 😊 | E15: PASS | G15: PASS | I15: Well Informed.
A16: 15 | B16: Is anything required before the appointment? | C16: Good | D16: Before your laser hair removal appointment, it's important to follow these guidelines: Avoid Sun Exposure: Make sure to stay out of the sun and avoid tanning beds for at least two weeks before the treatment. No Waxing or Plucking: Refrain from waxing or plucking the hair in the treatment area for at least four weeks prior. Shaving: It's usually recommended to shave the area a day before your appointment, as this helps the laser target the hair follicles more effectively. If you have any more questions or wish to schedule a session, just let me know! 😊 | E16: PASS | G16: PASS | I16: Well Informed.
A17: 16 | B17: Do you offer packages? | C17: Good | D17: Yes, we offer different laser hair removal packages! Here are the options: 1.5 Hour Laser Card: €150 3 Hour Laser Card: €285 6 Hour Laser Card: €459 These cards allow you to purchase sessions in bulk, and they do not expire. If you have more questions or wish to book a session, feel free to ask! 😊 | E17: PASS | G17: PASS | I17: Yes, we offer non-expiring laser cards that can be used across different treatment areas and shared with another person: 1.5 hours – €150 3 hours – €285 6 hours – €459. Each session is deducted in 15-minute intervals.
A18: 17 | B18: How do the packages work? For example, a laser card/package. | C18: Good | D18: With the laser cards, you purchase a set amount of time that can be used for multiple sessions. Here’s how it works: 1.5 Hour Card: €150 3 Hour Card: €285 6 Hour Card: €459 Minutes are deducted from the card in 15-minute increments per session. This means if you have a session that lasts 30 minutes, 30 minutes will be deducted from your total balance. If you have more questions or would like to book a session, just let me know! 😊 | E18: PASS | G18: PASS | I18: Our laser cards are purchased as a set amount of treatment time. Each appointment is deducted from the card in 15-minute intervals. The cards never expire, can be used for different body areas, and may also be shared with another person.
A19: 18 | B19: What is the cancellation policy? | C19: Good | D19: For cancellations, the policy is as follows: If you cancel or do not show up within 24 hours of your scheduled appointment time, your deposit is charged as a cancellation/no-show fee. Giving notice more than 24 hours in advance avoids this fee. Please note that cancellations within the 24-hour window cannot be done through the app or website; you must call us directly. If you have any more questions or want to schedule a session, just let me know! 😊 | E19: PASS | G19: PASS | I19: Well Informed.
A20: 19 | B20: How much deposit do I need to pay? | C20: Bad | D20: The team will confirm the exact deposit required for your appointment. If you have any more questions or wish to book a session, feel free to ask! 😊 | E20: FAIL | F20: No deposit is required for laser hair removal bookings. Any payment requirements for laser cards will be confirmed by reception when booking. If you need further assistance or have more questions, feel free to ask! 😊 | G20: PASS | H20: V2.1: no deposit; reception confirms laser-card payments | I20: No deposit is required when booking this treatment. Any payment requirements for treatment appointments or laser cards will be confirmed by our reception team when booking.

Sheet SEMI-PERMANENT MAKEUP
A1: # | B1: Question | C1: V1 verdict (Clarissa) | D1: Bot answer - first run (21 Jul) | E1: First-run grade | F1: Bot answer - after V2.1 fixes | G1: FINAL grade | H1: Grader comment | I1: Clarissa approved answer
A2: 1 | B2: Do you offer this service? | C2: Good | D2: It seems I couldn't retrieve specific details about the semi-permanent makeup service. However, I can confirm that we do offer it. If you're interested, I can assist you with scheduling a consultation or provide more information. Would you like to proceed with a booking? 😊 | E2: PARTIAL | G2: PARTIAL | H2: Confirms offering but 'couldn't retrieve details', no booking link | I2: Yes, we offer semi-permanent makeup treatments at Niumee, including microblading. You can book a free consultation through the following link: https://www.niumee.com/treatments/semi-permanent-make-up/
A3: 2 | B3: What does the treatment do? | C3: Good | D3: Semi-permanent makeup is a cosmetic tattooing technique that enhances facial features by implanting pigment into the skin. Here’s what you should know: Target Areas: Eyebrows (microblading, powder brows) Eyelids (eyeliner enhancements) Lips (lip blush or tint) Beauty marks Scalp hairline (light shading for density) Purpose: It reduces the need for daily makeup application, creating symmetry and definition in brows, lips, and eyes. Ideal for those with busy lifestyles or makeup sensitivities. How It Works: Using specialized equipment, pigment is deposited into the skin’s upper layers through techniques like microblading or machine shading. Proper aftercare is crucial, and results last around 1-3 years. Recovery Time: Healing takes about 5-14 days, with full results settling in 4-6 weeks. Benefits: Enhances appearance, requiring minimal maintenance. If you have any further questions or are ready to book a consultation, just let me know! 😊 You can find more details here: https://niumee.com/treatments/semi-permanent-make-up/ | E3: PASS | G3: PASS | I3: Nice response
A4: 3 | B4: What are the benefits? | C4: Good | D4: Here are the benefits of semi-permanent makeup: Long-lasting results: Minimizes the need for daily makeup application, lasting 1-3 years. Enhances natural beauty: Defines and enhances key facial features, such as eyebrows, lips, and eyes. Convenience: Perfect for those with busy lifestyles, providing a polished look without the daily hassle. Customizable: Techniques like microblading and shading allow for personalized results that suit individual preferences. Symmetry: Helps create a more balanced appearance, especially for those with uneven features. Confidence boost: Many clients feel more confident and comfortable without makeup. If you'd like to explore this service further or book a consultation, please let me know! 😊 | E4: PASS | G4: PASS | I4: Nice response
A5: 4 | B5: Are there any side effects or contraindications? | C5: Good | D5: Semi-permanent makeup does come with some potential side effects and contraindications. Here are the details: Possible Side Effects: Mild redness and swelling: Common immediately after the procedure, typically subsiding within a few hours. Flaking and peeling: As the skin heals, mild flaking can occur, usually lasting about a week. Allergic reactions: Some individuals may experience allergic reactions to the pigments used. Contraindications: Pregnancy and breastfeeding: Generally advised against during this time. Certain skin conditions: Active acne, eczema, or psoriasis in the treated areas could complicate the process. Blood disorders: Individuals with certain blood disorders or on anticoagulant medication should consult with a healthcare provider beforehand. Keloid scarring: Those prone to keloids may not be suitable candidates. It’s crucial to discuss any medical conditions during your consultation to determine if you are a suitable candidate for the treatment. Would you like to book a consultation for more personalized information? 😊 You can also find more details here: https://niumee.com/treatments/semi-permanent-make-up/ | E5: PASS | G5: PASS | I5: Nice response
A6: 5 | B6: Can I have sun exposure after the treatment? If yes, after how long? | C6: Good | D6: After the semi-permanent makeup treatment, it’s important to avoid sun exposure for at least 24 to 48 hours. Direct sunlight can cause irritation and affect the healing process of the treated areas. Once you’ve passed this initial period, it’s still advisable to wear sunscreen on the treated areas to protect the pigment and promote better healing. If you have any further questions or would like to schedule a consultation, just let me know! 😊 | E6: PASS | G6: PASS | I6: Nice response
A7: 6 | B7: Are there any precautions before or after the treatment? | C7: Good | D7: Here are the precautions you should take before and after the semi-permanent makeup treatment: Before the Treatment: Avoid Alcohol and Caffeine: Stop consuming alcohol and caffeine for at least 24 hours prior, as they can increase bleeding. Avoid Skin Irritation: Do not exfoliate or use strong skin treatments on the area a few days beforehand. Discuss Medical History: Talk to your technician about any medications or conditions, including medications that may affect healing. After the Treatment: Avoid Sun Exposure: Stay out of direct sunlight for at least 24 to 48 hours. After this, use sunscreen on the treated areas. Avoid Makeup: Do not apply makeup to the treated areas for at least a week to allow healing. Follow Aftercare Instructions: Keep the area clean and moisturized as advised by your technician. These precautions help ensure the best results and safe healing. If you have further questions or wish to book a consultation, feel free to ask! 😊 You can find more information here: https://niumee.com/treatments/semi-permanent-make-up/ | E7: PASS | G7: PASS | I7: Nice response
A8: 7 | B8: How much does it cost? | C8: Good | D8: I will need to confirm the exact cost of the semi-permanent makeup treatment, as I couldn't retrieve that information right now. Would you like to book a consultation where we can discuss the details further? 😊 | E8: FAIL | F8: The starting price for semi-permanent makeup is EUR200, but the final cost can vary based on the area and technique. It's recommended to have a free consultation to determine the exact price. Would you like to schedule that consultation or have more questions? 😊 | G8: PASS | H8: V2.1: from EUR200 + free consultation offer | I8: Semi-permanent makeup treatments start from €200. The final price depends on the area and technique selected. You can book a free consultation to discuss your desired result and confirm the exact cost here: https://www.niumee.com/treatments/semi-permanent-make-up/
A9: 8 | B9: Who performs this treatment? | C9: Good | D9: It seems I couldn't retrieve specific information about who performs the semi-permanent makeup treatment at this moment. Would you like to schedule a consultation where we can discuss this further? 😊 | E9: FAIL | F9: Semi-permanent makeup is performed by the following skilled professionals: 1. Mehmet Cakir (master) 2. Melanie Sciberras 3. Ilona Abela 4. Magda. If you have any more questions about the treatments or want to schedule a consultation, just let me know! 😊 | G9: PASS | H9: V2.1: Mehmet Cakir (master), Melanie, Ilona, Magda | I9: Semi-permanent makeup treatments are performed by our qualified and experienced semi-permanent makeup specialists; Mehmet, Magda and Melanie
A10: 9 | B10: How long does the treatment take? | C10: Good | D10: The semi-permanent makeup treatment typically takes about 1 to 2 hours, depending on the area being treated. Additional details: The healing process on the surface takes 5 to 14 days, with full results settling in about 4 to 6 weeks. This treatment enhances features like eyebrows, lips, and eyeliner for a long-lasting, natural look. Would you like to discuss booking a consultation? 😊 | E10: PASS | G10: PASS | I10: Nice response
A11: 10 | B11: What is the treatment protocol? | C11: Good | D11: The treatment protocol for semi-permanent makeup is as follows: Consultation: Discuss your goals and concerns with the technician. Mapping and preparation take place in this phase. Numbing: The area to be treated is numbed for comfort during the procedure. Application: The technician uses specialized equipment to deposit pigments into the skin with precision. Aftercare: Adhering to aftercare instructions is essential for proper healing. Follow-up: A follow-up session is often recommended to perfect the results. Would you like to schedule a consultation to go over these details further? 😊 | E11: PASS | G11: PASS | I11: The process begins with a free consultation to discuss your desired colour, shape, and finish. On the treatment day, a numbing cream is applied before mineral-based pigment is carefully deposited into the skin. The appointment usually takes 75–180 minutes, and a touch-up may be required after 4–6 weeks, depending on the treatment selected.
A12: 11 | B12: After how long is the treatment repeated? | C12: Good | D12: The semi-permanent makeup treatment is typically repeated every 1 to 3 years, depending on skin type, the pigments used, and aftercare followed. Regular touch-ups can help maintain the results. Would you like to schedule a consultation to discuss this further? 😊 | E12: PASS | G12: PASS | I12: Nice response
A13: 12 | B13: How many sessions are required? | C13: Good | D13: Typically, 1 to 2 sessions are required to achieve the desired results for semi-permanent makeup. A follow-up session may be recommended for touch-ups to perfect the look. Would you like to schedule a consultation to go over this in more detail? 😊 | E13: PASS | G13: PASS | I13: Nice response
A14: 13 | B14: Is it painful? | C14: Good | D14: The sensation during the semi-permanent makeup treatment can vary, but most clients find it manageable. A numbing cream is applied beforehand to minimize any discomfort. Some may experience mild sensations, similar to light scratching. Would you like to schedule a consultation to discuss this further? 😊 | E14: PASS | G14: PASS | I14: Nice response
A15: 14 | B15: What is the minimum or maximum age allowed for this treatment? | C15: Good | D15: The minimum age for semi-permanent makeup treatment is typically 18 years. There isn't a strict maximum age, as long as the individual is in good health and suitable for the procedure. Would you like to schedule a consultation to discuss this further? 😊 | E15: PASS | G15: PASS | I15: Nice response
A16: 15 | B16: Is anything required before the appointment? | C16: Good | D16: Before your semi-permanent makeup appointment, it's recommended to: Avoid alcohol and blood thinners for at least 24 hours. Ensure your skin is in good condition — any irritation or breakouts should be cleared up prior. Arrive without makeup on the areas to be treated. Would you like to schedule a consultation to discuss this further? 😊 | E16: PASS | G16: PASS | I16: Nice response
A17: 16 | B17: Do you offer packages? | C17: Good | D17: Currently, we do not offer packages for semi-permanent makeup treatments. Each session is priced individually, and follow-up sessions may be needed to achieve the desired results. Would you like to schedule a consultation to discuss this further? 😊 | E17: PASS | G17: PASS | I17: Nice response
A18: 17 | B18: What is the cancellation policy? | C18: Good | D18: For semi-permanent makeup treatments, if you need to cancel or reschedule, please do so with more than 24 hours' notice to avoid a cancellation fee. This allows us to offer the appointment to someone else. Would you like to schedule a consultation to discuss this further? 😊 | E18: PASS | G18: PASS | I18: If you need to cancel or reschedule your appointment, please inform us at least 24 hours in advance. Cancellations made with less than 24 hours’ notice may incur a €50 cancellation fee.
A19: 18 | B19: How much deposit do I need to pay? | C19: Good | D19: The exact deposit amount for semi-permanent makeup treatments will need to be confirmed by our team. Would you like to schedule a consultation to discuss this further? 😊 | E19: FAIL | F19: A EUR100 deposit is required for semi-permanent makeup. Since the starting price for the treatment is EUR200, I'd recommend scheduling a free consultation to confirm the exact cost based on the area and technique you're interested in. Would you like to arrange that consultation? 😊 | G19: PASS | H19: V2.1: EUR100 deposit stated | I19: Nice response

Sheet FACIALS
A1: # | B1: Question | C1: V1 verdict (Clarissa) | D1: Bot answer - first run (21 Jul) | E1: First-run grade | F1: Bot answer - after V2.1 fixes | G1: FINAL grade | H1: Grader comment | I1: Clarissa approved answer
A2: 1 | B2: Do you offer this service? | C2: Good | D2: We offer a variety of facial treatments! Here are the available options: 1) 3D Scanner Facial analysis (30 min) 2) Derma planing- facial (50 min) 3) Facial - Dermalogica Exo Booster Microneedling (90 min) 4) Facial - Dermalogica Firm + Lift / Face + Neck (105 min) 5) Facial - Dermalogica LuminFusion (90 min) 6) Facial - Dermalogica MelanoPro (60 min) 7) Facial - Dermalogica Microneedling Face & Neck (75 min) 8) Facial - Dermalogica Nanoinfusion (90 min) Please reply with the NUMBER of the treatment you are interested in! 😊 | E2: PARTIAL | F2: It looks like we have several facial options available! Please take a look at these: 1) 3D Scanner Facial analysis (30 min) 2) Derma Planing Facial (50 min) 3) Facial - Dermalogica Exo Booster Microneedling (90 min) 4) Facial - Dermalogica Firm + Lift / Face + Neck (105 min) 5) Facial - Dermalogica LuminFusion (90 min) 6) Facial - Dermalogica MelanoPro (60 min) 7) Facial - Dermalogica Microneedling Face & Neck (75 min) 8) Facial - Dermalogica Nanoinfusion (90 min) Please reply with the NUMBER of the service you’re interested in! 😊 | G2: PARTIAL | H2: Menu OK; still no booking link | I2: Add link to book a free consult or facial
A3: 2 | B3: What does the treatment do? | C3: Good | D3: It seems I'm unable to retrieve the specific details for the facial treatments at the moment. However, generally, facials are designed to cleanse, nourish, and rejuvenate the skin, addressing various skin concerns such as hydration, anti-aging, and improving overall skin texture. If you have a particular treatment in mind from the list I provided earlier, I recommend scheduling a consultation with one of our therapists or doctors, who can provide more tailored information. Let me know if you’d like to choose a specific treatment or if there's anything else I can assist you with! 😊 | E3: PARTIAL | F3: It seems there's a temporary issue retrieving detailed descriptions for the facial treatments. However, generally: Microneedling stimulates collagen production and helps improve skin texture. Firming facials aim to lift and tighten the skin. Exo Booster facials focus on enhancing overall skin appearance with additional nutrients. Please let me know if you would like more specific information or have another treatment in mind! 😊 | G3: PARTIAL | H3: Generic info given, flagged a retrieval issue
A4: 3 | B4: What are the benefits? | C4: Good | D4: Could you please specify which facial treatment you're interested in from the options I previously listed? This will help me provide you with the specific benefits related to that treatment. Here's a quick reminder of the treatments available: 1) 3D Scanner Facial analysis (30 min) 2) Derma planing- facial (50 min) 3) Facial - Dermalogica Exo Booster Microneedling (90 min) 4) Facial - Dermalogica Firm + Lift / Face + Neck (105 min) 5) Facial - Dermalogica LuminFusion (90 min) 6) Facial - Dermalogica MelanoPro (60 min) 7) Facial - Dermalogica Microneedling Face & Neck (75 min) 8) Facial - Dermalogica Nanoinfusion (90 min) Please reply with the NUMBER of the treatment you're curious about! 😊 | E4: FAIL | F4: Hello Astra! I'm Nima, the virtual receptionist at Niumee Medical Aesthetics. The benefits of our facial treatments can vary quite a bit depending on the specific service. Here are some general benefits associated with common facial treatments: Microneedling: Stimulates collagen production, improves skin texture, and reduces fine lines. Firming Facials: Aims to tighten and lift the skin, providing a more youthful appearance. Exo Booster Facials: Enhances overall skin appearance using specialized nutrients. If you let me know which specific treatment you're interested in, I can provide more tailored benefits! 😊 | G4: PASS | H4: V2.1: answers generally, no menu-demand
A5: 4 | B5: Are there any side effects or contraindications? | C5: Good | D5: Could you please specify which specific facial treatment you are inquiring about? Knowing the treatment will help me provide you with accurate information regarding any potential side effects or contraindications. Here are the options again: 1) 3D Scanner Facial analysis (30 min) 2) Derma planing- facial (50 min) 3) Facial - Dermalogica Exo Booster Microneedling (90 min) 4) Facial - Dermalogica Firm + Lift / Face + Neck (105 min) 5) Facial - Dermalogica LuminFusion (90 min) 6) Facial - Dermalogica MelanoPro (60 min) 7) Facial - Dermalogica Microneedling Face & Neck (75 min) 8) Facial - Dermalogica Nanoinfusion (90 min) Please reply with the NUMBER of the treatment you're interested in! 😊 | E5: FAIL | F5: For each facial treatment, there are generally some side effects and contraindications to keep in mind: Microneedling: - Side Effects: Redness, swelling, and minor bruising are common after treatment. These typically resolve within a few days. - Contraindications: Not recommended for individuals with active skin infections, certain skin conditions (like eczema or psoriasis), or those on blood-thinning medications. Firming Facials: - Side Effects: Mild redness and irritation. - Contraindications: Sensitive skin or allergies to specific ingredients used in the facial. Exo Booster Facials: - Side Effects: Possible redness or sensitivity. - Contraindications: Allergies to components in the treatment. To ensure safety, it's best to discuss any concerns during a consultation. Let me know if you'd like to schedule one! 😊 | G5: PASS | H5: V2.1: answered generally
A6: 5 | B6: Can I have sun exposure after the treatment? If yes, after how long? | C6: Good | D6: Could you please specify which facial treatment you're inquiring about? The guidelines regarding sun exposure can vary depending on the specific treatment, so knowing the exact one will help me give you the best advice. Here are the treatments again for your reference: 1) 3D Scanner Facial analysis (30 min) 2) Derma planing- facial (50 min) 3) Facial - Dermalogica Exo Booster Microneedling (90 min) 4) Facial - Dermalogica Firm + Lift / Face + Neck (105 min) 5) Facial - Dermalogica LuminFusion (90 min) 6) Facial - Dermalogica MelanoPro (60 min) 7) Facial - Dermalogica Microneedling Face & Neck (75 min) 8) Facial - Dermalogica Nanoinfusion (90 min) Please reply with the NUMBER of the treatment you are curious about! 😊 | E6: FAIL | F6: After most facial treatments, it's generally advisable to avoid sun exposure for 24 to 48 hours. This helps protect your skin and allows it to recover without potential irritation from UV rays. For treatments like microneedling, it’s best to avoid direct sun for at least 48 hours to minimize any risk of pigmentation changes. Always ensure to use a good sunscreen afterward if you need to be in the sun. If you have any further questions or need specific advice regarding your treatment, feel free to ask! 😊 | G6: PASS | H6: V2.1: answered
A7: 6 | B7: Are there any precautions before or after the treatment? | C7: Good | D7: Could you please specify which facial treatment you're inquiring about? Knowing the specific treatment will help me provide you with the relevant precautions before and after the treatment. Here are the options for you to choose from: 1) 3D Scanner Facial analysis (30 min) 2) Derma planing- facial (50 min) 3) Facial - Dermalogica Exo Booster Microneedling (90 min) 4) Facial - Dermalogica Firm + Lift / Face + Neck (105 min) 5) Facial - Dermalogica LuminFusion (90 min) 6) Facial - Dermalogica MelanoPro (60 min) 7) Facial - Dermalogica Microneedling Face & Neck (75 min) 8) Facial - Dermalogica Nanoinfusion (90 min) Please reply with the NUMBER of the treatment you're interested in! 😊 | E7: FAIL | F7: Before and after facial treatments, it’s essential to take some precautions: Before Treatment: Avoid using retinoids or exfoliating products for at least 3 days prior. Drink plenty of water to keep your skin hydrated. Avoid sun exposure or tanning beds for a week to minimize sensitivity. After Treatment: Avoid sun exposure for at least 24 to 48 hours. Do not apply makeup for a few hours following the treatment. Keep the skin moisturized and consider using gentle products to avoid irritation. Avoid strenuous exercise and sweat-inducing activities for at least 24 hours. If you have any more specific questions or need to schedule a consultation, just let me know! 😊 | G7: PASS | H7: V2.1: answered
A8: 7 | B8: How much does it cost? | C8: Good | D8: Could you please specify which facial treatment you are inquiring about? The prices can vary based on the specific treatment you choose. Here are the treatments for you to pick from: 1) 3D Scanner Facial analysis (30 min) 2) Derma planing- facial (50 min) 3) Facial - Dermalogica Exo Booster Microneedling (90 min) 4) Facial - Dermalogica Firm + Lift / Face + Neck (105 min) 5) Facial - Dermalogica LuminFusion (90 min) 6) Facial - Dermalogica MelanoPro (60 min) 7) Facial - Dermalogica Microneedling Face & Neck (75 min) 8) Facial - Dermalogica Nanoinfusion (90 min) Please reply with the NUMBER of the treatment you're interested in! 😊 | E8: PARTIAL | F8: It seems I couldn't retrieve the specific pricing for facial treatments at the moment. The team will confirm the exact cost for you shortly. If you have any more questions or would like to discuss treatments in more detail, please let me know! 😊 | G8: FAIL | H8: Defers to team; per-facial prices exist in catalog
A9: 8 | B9: Who performs this treatment? | C9: Good | D9: Could you please specify which facial treatment you are inquiring about? Each treatment may be performed by different therapists. Here are the options you can choose from: 1) 3D Scanner Facial analysis (30 min) 2) Derma planing- facial (50 min) 3) Facial - Dermalogica Exo Booster Microneedling (90 min) 4) Facial - Dermalogica Firm + Lift / Face + Neck (105 min) 5) Facial - Dermalogica LuminFusion (90 min) 6) Facial - Dermalogica MelanoPro (60 min) 7) Facial - Dermalogica Microneedling Face & Neck (75 min) 8) Facial - Dermalogica Nanoinfusion (90 min) Please reply with the NUMBER of the treatment you're interested in! 😊 | E9: FAIL | F9: I couldn't find specific information about who performs facial treatments at this time. However, I recommend checking with our team, who will provide the details for you shortly. If you have any other questions or need assistance with something else, feel free to ask! 😊 | G9: FAIL | H9: Defers; no facials staff answer configured
A10: 9 | B10: How long does the treatment take? | C10: Good | D10: Could you please specify which facial treatment you are inquiring about? The duration can vary depending on the specific treatment. Here are the treatments for you to choose from: 1) 3D Scanner Facial analysis (30 min) 2) Derma planing- facial (50 min) 3) Facial - Dermalogica Exo Booster Microneedling (90 min) 4) Facial - Dermalogica Firm + Lift / Face + Neck (105 min) 5) Facial - Dermalogica LuminFusion (90 min) 6) Facial - Dermalogica MelanoPro (60 min) 7) Facial - Dermalogica Microneedling Face & Neck (75 min) 8) Facial - Dermalogica Nanoinfusion (90 min) Please reply with the NUMBER of the treatment you're interested in! 😊 | E10: FAIL | F10: I'm unable to retrieve the specific duration for facial treatments at this time. However, I will have our team confirm this information for you shortly. If there's anything else you need or if you have more questions, please let me know! 😊 | G10: FAIL | H10: Defers although durations are in its own menu
A11: 10 | B11: What is the treatment protocol? | C11: Good | D11: Could you please specify which facial treatment you're inquiring about? The treatment protocol can vary depending on the specific treatment you choose. Here are the options for you: 1) 3D Scanner Facial analysis (30 min) 2) Derma planing- facial (50 min) 3) Facial - Dermalogica Exo Booster Microneedling (90 min) 4) Facial - Dermalogica Firm + Lift / Face + Neck (105 min) 5) Facial - Dermalogica LuminFusion (90 min) 6) Facial - Dermalogica MelanoPro (60 min) 7) Facial - Dermalogica Microneedling Face & Neck (75 min) 8) Facial - Dermalogica Nanoinfusion (90 min) Please reply with the NUMBER of the treatment you're interested in! 😊 | E11: FAIL | F11: I couldn't find specific information on the treatment protocol for facial treatments at this moment. I recommend checking with our team for detailed guidance on this. If you have any other queries or need assistance, just let me know! 😊 | G11: FAIL | H11: Defer-loop
A12: 11 | B12: After how long is the treatment repeated? | C12: Good | D12: Could you please specify which facial treatment you are inquiring about? The frequency of repeating the treatment can vary based on the specific procedure you choose. Here are the options for you: 1) 3D Scanner Facial analysis (30 min) 2) Derma planing- facial (50 min) 3) Facial - Dermalogica Exo Booster Microneedling (90 min) 4) Facial - Dermalogica Firm + Lift / Face + Neck (105 min) 5) Facial - Dermalogica LuminFusion (90 min) 6) Facial - Dermalogica MelanoPro (60 min) 7) Facial - Dermalogica Microneedling Face & Neck (75 min) 8) Facial - Dermalogica Nanoinfusion (90 min) Please reply with the NUMBER of the treatment you're interested in! 😊 | E12: FAIL | F12: I currently don't have information on how long until the treatment can be repeated. I'll have the team confirm this detail for you. If you have more questions or need further assistance, please let me know! 😊 | G12: FAIL | H12: Defer-loop
A13: 12 | B13: How many sessions are required? | C13: Good | D13: Could you please specify which facial treatment you are inquiring about? The number of sessions required can vary based on the specific treatment you choose. Here are the treatments for you to choose from: 1) 3D Scanner Facial analysis (30 min) 2) Derma planing- facial (50 min) 3) Facial - Dermalogica Exo Booster Microneedling (90 min) 4) Facial - Dermalogica Firm + Lift / Face + Neck (105 min) 5) Facial - Dermalogica LuminFusion (90 min) 6) Facial - Dermalogica MelanoPro (60 min) 7) Facial - Dermalogica Microneedling Face & Neck (75 min) 8) Facial - Dermalogica Nanoinfusion (90 min) Please reply with the NUMBER of the treatment you're interested in! 😊 | E13: FAIL | F13: I don't have the specific information on how many sessions are required for facial treatments. I will have our team confirm this detail for you. If there's anything else you need or more questions arise, feel free to let me know! 😊 | G13: FAIL | H13: Defer-loop
A14: 13 | B14: Is it painful? | C14: Good | D14: The sensation during treatment can vary depending on the specific facial treatment chosen. Some treatments might involve minimal discomfort, while others could cause more sensitivity. Could you please specify which facial treatment you're asking about? Here are the options: 1) 3D Scanner Facial analysis (30 min) 2) Derma planing- facial (50 min) 3) Facial - Dermalogica Exo Booster Microneedling (90 min) 4) Facial - Dermalogica Firm + Lift / Face + Neck (105 min) 5) Facial - Dermalogica LuminFusion (90 min) 6) Facial - Dermalogica MelanoPro (60 min) 7) Facial - Dermalogica Microneedling Face & Neck (75 min) 8) Facial - Dermalogica Nanoinfusion (90 min) Please reply with the NUMBER of the treatment you're interested in! 😊 | E14: PARTIAL | F14: I currently don’t have details on whether the treatment is painful. I will check with our team to confirm this information for you. If you have any more questions or if there's anything else I can assist you with, just let me know! 😊 | G14: FAIL | H14: Defer-loop
... A16: 15 | B16: Is anything required before the appointment? | C16: Good | D16: Whether anything is required before the appointment can depend on the specific facial treatment chosen. Could you please specify which treatment you're referring to? Here are the options: 1) 3D Scanner Facial analysis (30 min) 2) Derma planing- facial (50 min) 3) Facial - Dermalogica Exo Booster Microneedling (90 min) 4) Facial - Dermalogica Firm + Lift / Face + Neck (105 min) 5) Facial - Dermalogica LuminFusion (90 min) 6) Facial - Dermalogica MelanoPro (60 min) 7) Facial - Dermalogica Microneedling Face & Neck (75 min) 8) Facial - Dermalogica Nanoinfusion (90 min) Please reply with the NUMBER of the treatment you're interested in! 😊 | E16: PARTIAL | F16: I currently don't have information on whether anything is required before the appointment. I will check with our team to confirm this for you. If you have any other questions or need further assistance, feel free to let me know! 😊 | G16: FAIL | H16: Defer-loop
A17: 16 | B17: Do you offer packages? | C17: Good | D17: We do offer some packages, but the details can vary by treatment category. Could you please provide more details on which kind of treatment you are interested in? Here are the facial options again: 1) 3D Scanner Facial analysis (30 min) 2) Derma planing- facial (50 min) 3) Facial - Dermalogica Exo Booster Microneedling (90 min) 4) Facial - Dermalogica Firm + Lift / Face + Neck (105 min) 5) Facial - Dermalogica LuminFusion (90 min) 6) Facial - Dermalogica MelanoPro (60 min) 7) Facial - Dermalogica Microneedling Face & Neck (75 min) 8) Facial - Dermalogica Nanoinfusion (90 min) Please reply with the NUMBER of the treatment you're interested in! 😊 | E17: FAIL | F17: I don't have information on whether we offer packages for treatments. I will check with our team to confirm this for you. If there's anything else you need or any other questions, please let me know! 😊 | G17: FAIL | H17: Defer-loop; no-packages note didn't surface | I17: We don't offer packages for waxing and facials
A18: 17 | B18: What is the cancellation policy? | C18: Good | D18: For our cancellation policy: If you cancel or do not show up within 24 hours of your scheduled appointment time, your deposit will be charged as a cancellation/no-show fee. If you cancel more than 24 hours in advance, there is no charge. Cancellations within the 24-hour window cannot be done through the app or website; you must call or send a WhatsApp message directly. If you need more details about a specific treatment, please let me know! 😊 | E18: PASS | F18: I currently don't have the specific details about the cancellation policy. I will check with our team and get back to you with the information. If you have any other questions or need further assistance, just let me know! 😊 | G18: FAIL | H18: Defer-loop (it knew this in the first run)
A19: 18 | B19: How much deposit do I need to pay? | C19: Good | D19: The deposit amount required can vary by treatment, and this category isn’t a standard deposit tier. The team will confirm the exact deposit amount for your specific treatment. If you let me know which treatment you're interested in, I can help further! 😊 | E19: FAIL | F19: I don't have the exact deposit amount required for your appointment. I will check with our team to confirm this for you. If you have any other questions or need further assistance, just let me know! 😊 | G19: FAIL | H19: Defer-loop; EUR20 tier didn't surface. Known issue: after several failed lookups the session copies its own 'I'll check with the team' pattern | I19: This is wrong. Deposit is 20 euros.

Sheet NAILS
A1: # | B1: Question | C1: V1 verdict (Clarissa) | D1: Bot answer - first run (21 Jul) | E1: First-run grade | F1: Bot answer - after V2.1 fixes | G1: FINAL grade | H1: Grader comment | I1: Clarissa approved answer
A2: 1 | B2: Do you offer this service? | C2: Good | D2: We offer several nail services! Here are your options: 1) Add on Air Brush Nail art (15 min) 2) ADD on French or nail art (15 min) 3) Air Brush nail art (15 min) 4) Extra Long Length Full set nails (120 min) 5) Full Set - Long length Gel Nails (90 min) 6) Full set nails - Short/Medium Length (90 min) 7) Infills- Long length Nails (90 min) 8) Ingrown toe nail removal (1-2 sides) (30 min) Please reply with just the NUMBER corresponding to the service you're interested in! 😊 | E2: PASS | G2: PASS | I2: Good response
A3: 2 | B3: Can I just come to apply gel polish on my feet? | C3: Good | D3: It seems I need to confirm this specifically with our team. We do offer gel polish services for feet, but I'll need to verify the details, including pricing and availability. Would you like me to follow up on this and get back to you shortly? 😊 | E3: PARTIAL | G3: PARTIAL | H3: Deferred to team; approved describes soak/scrub/colour pedicure | I3: This is mentioning the soak, scrub and color application ped
A4: 3 | B4: I dont want the soak and scrub - i just want them to apply color, is this possible? | C4: Good | D4: I understand you're looking for just the gel polish application without the soak and scrub. Let me check this with our team to confirm if that's an option available for you. I'll follow up shortly with the information! 😊 | E4: PASS | G4: PASS | H4: Deferring OK - service doesn't exist yet per Clarissa | I4: We need to add this on our services list as we do not have this as an option
A5: 4 | B5: Are there any side effects or contraindications? | C5: Good | D5: I’ll need to check with our team to gather accurate information regarding any potential side effects or contraindications related to the gel polish service. I'll make sure to follow up with you shortly! 😊 | E5: FAIL | F5: For nail services, there are generally no serious side effects or contraindications if performed by professionals. However, there are a few considerations: Nail Damage: Overuse of certain treatments (like gels or acrylics) can weaken natural nails. Allergies: Some clients may have allergic reactions to specific nail products. Infections: Improper techniques during nail care can lead to infections or irritations. Skin Sensitivities: Individuals with sensitive skin around the nails should be cautious. It's always best to discuss your specific needs with the technician on the day of your appointment. Do you have any other questions or would you like to book an appointment? 😊 | G5: PASS | H5: V2.1: answered | I5: Good response
A6: 5 | B6: Are there any precautions before or after the treatment? | C6: Good | D6: I will check for any precautions you should take before or after the gel polish treatment. I'll get back to you shortly with that information! 😊 | E6: FAIL | F6: For nail treatments, here are some common precautions to consider before and after: Before Treatment: Consultation: It’s helpful to inform the technician about any allergies or sensitivities you may have. Clean Nails: Arrive with clean nails to ensure the best treatment results. Avoid Moisturizers: Do not apply lotion or oil to your hands or nails prior to treatment to allow for better adhesion of products. After Treatment: Drying Time: If polish is applied, give it adequate time to dry fully to avoid smudging. Moisturization: Apply moisturizer to keep your hands hydrated, especially focusing on the cuticles. Avoid Harsh Chemicals: Try to avoid exposing your nails to harsh cleaning products immediately after treatment. Protective Measures: Consider wearing gloves when doing chores to protect your nails. If you have specific concerns or would like to book an appointment, just let me know! 😊 | G6: PASS | H6: V2.1: answered | I6: Good response
A7: 6 | B7: How much does infills cost? | C7: Good | D7: The cost for infills is starting from €45. If you have any other questions or need further information, feel free to ask! 😊 | E7: FAIL | F7: The cost for infills of long-length nails is starting from €45. Duration for this service is approximately 90 minutes. If you would like to book an appointment or have any other questions, just let me know! 😊 | G7: FAIL | H7: Still EUR45 (Zenoti catalog price). Clarissa wrote EUR40 in one answer and EUR50 in another - needs her confirmation before we change data | I7: infills are 40
A8: 7 | B8: Who performs this treatment? | C8: Good | D8: It seems I couldn't find specific details on who performs the infills treatment at this moment. Typically, our nail technicians handle treatments like this. Would you like me to confirm the names of our nail technicians for you? 😊 | E8: FAIL | F8: The nail treatments, including infills, are performed by our skilled nail technicians: Frima Dag-o Mary Gorret Nabukeera Nashra Apad Natalia Dabrowska If you have any specific requests or would like to book an appointment with one of them, just let me know! 😊 | G8: PASS | H8: V2.1: all four nail technicians named | I8: Needs to include all the names of nail techs
A9: 8 | B9: How long does the treatment take? | C9: Good | D9: The infills treatment typically takes around 90 minutes. If you have any other questions or need more information, just let me know! 😊 | E9: PASS | G9: PASS | I9: Good response
A10: 9 | B10: Can i have a breakdown of prices for mani and pedi services | C10: Good | D10: Here’s a breakdown of the prices for manicure and pedicure services: Manicure Options: Basic Manicure: €20 (Duration: 30 minutes) Pedicure Options: Luxury Pedicure: €45 (Duration: 90 minutes) Gehwol Herbal Pedicure: €40 (Duration: 60 minutes) Gehwol Herbal Pedicure & Polish: €45 (Duration: 75 minutes) Teen + Gehwol Herbal Pedicure: €28 (Duration: 60 minutes) Teen + Gehwol Herbal Pedicure & Polish: €32 (Duration: 75 minutes) If you need any more information or have further questions, feel free to ask! 😊 | E10: PARTIAL | G10: PARTIAL | H10: Good breakdown but thin manicure options, no infills | I10: Included infills at 50 euros
A11: 10 | B11: Does the gehwol pedicure include color application? | C11: Good | D11: The Gehwol Herbal Pedicure does not include color application. However, you can opt for the Gehwol Herbal Pedicure & Polish, which does include color application. If you have any other questions or need further details, just let me know! 😊 | E11: PARTIAL | G11: PARTIAL | H11: Correct yes/no but didn't give 40/45 price difference | I11: Mention the price difference. If client wants a gehwol pedicure price is 40 euros, should you wish to book a gehwol pedi with color application the price is 45
A12: 11 | B12: After how long is the treatment repeated? | C12: Good | D12: The Gehwol Herbal Pedicure is recommended to be repeated every 6 weeks for optimal results. If you have any more questions or need further assistance, just let me know! 😊 | E12: PASS | G12: PASS | I12: Good response
A13: 12 | B13: Is anything required before the appointment? | C13: Good | D13: Generally, there are no specific requirements before your appointment for the Gehwol Herbal Pedicure. However, it is always a good idea to come with clean feet to enhance the treatment experience. If you have any further questions or need more details, just let me know! 😊 | E13: PASS | G13: PASS | I13: Good response
